<?xml version="1.0" encoding="utf-8"?>


<robot name="robot">
  <mujoco>
    <compiler discardvisual="false" discardcollision="false" meshdir="meshes"/>
  </mujoco>
  <link name="world"></link>
  <joint name="floating_base_joint" type="floating">
    <parent link="world"/>
    <child link="base_link"/>
  </joint>

  <link name="base_link">
    <visual><origin xyz="0 0 0" rpy="0 0 0" /><geometry><sphere radius="0.01" /></geometry></visual>
    <collision><origin xyz="0 0 0" rpy="0 0 0" /><geometry><sphere radius="0.01" /></geometry></collision>
    <inertial><origin xyz="0 0 0" rpy="0 0 0" /><mass value="1" /><inertia ixx="0.4" ixy="0" ixz="0" iyy="0.4" iyz="0" izz="0.4" /></inertial>
  </link>

  <!-- ========= LEFT LEG ========= -->
  <joint name="left_hip_pitch_joint" type="revolute">
    <parent link="base_link" />
    <child link="left_hip_pitch_link" />
    <origin xyz="0 0.026 -0.043" rpy="0 0 0" />
    <axis xyz="0 1 0"/>
    <limit effort="1000.0" lower="-2" upper="2" velocity="0.5"/>
  </joint>
  <link name="left_hip_pitch_link">
    <visual><origin xyz="0 0 0" rpy="0 0 0" /><geometry><sphere radius="0.01" /></geometry></visual>
    <collision><origin xyz="0 0 0" rpy="0 0 0" /><geometry><sphere radius="0.01" /></geometry></collision>
    <inertial><origin xyz="0 0 0" rpy="0 0 0" /><mass value="1" /><inertia ixx="0.4" ixy="0" ixz="0" iyy="0.4" iyz="0" izz="0.4" /></inertial>
  </link>

  <joint name="left_hip_roll_joint" type="revolute">
    <parent link="left_hip_pitch_link" />
    <child link="left_hip_roll_link" />
    <origin xyz="0 0 0" rpy="0 0 0" />
    <axis xyz="1 0 0"/>
    <limit effort="1000.0" lower="-1" upper="1" velocity="0.5"/>
  </joint>
  <link name="left_hip_roll_link">
    <visual><origin xyz="0 0 0" rpy="0 0 0" /><geometry><sphere radius="0.01" /></geometry></visual>
    <collision><origin xyz="0 0 0" rpy="0 0 0" /><geometry><sphere radius="0.01" /></geometry></collision>
    <inertial><origin xyz="0 0 0" rpy="0 0 0" /><mass value="1" /><inertia ixx="0.4" ixy="0" ixz="0" iyy="0.4" iyz="0" izz="0.4" /></inertial>
  </link>

  <joint name="left_hip_yaw_joint" type="revolute">
    <parent link="left_hip_roll_link" />
    <child link="left_hip_yaw_link" />
    <origin xyz="0 0 0" rpy="0 0 0" />
    <axis xyz="0 0 1"/>
    <limit effort="1000.0" lower="-2" upper="2" velocity="0.5"/>
  </joint>
  <link name="left_hip_yaw_link">
    <visual><origin xyz="0.005 0.021 -0.08" rpy="0 0 0" /><geometry><cylinder radius="0.01" length="0.16" /></geometry></visual>
    <collision><origin xyz="0.005 0.021 -0.08" rpy="0 0 0" /><geometry><sphere radius="0.01" /></geometry></collision>
    <inertial><origin xyz="0.005 0.021 -0.08" rpy="0 0 0" /><mass value="1" /><inertia ixx="0.4" ixy="0" ixz="0" iyy="0.4" iyz="0" izz="0.4" /></inertial>
  </link>

  <joint name="left_knee_pitch_joint" type="revolute">
    <parent link="left_hip_yaw_link" />
    <child link="left_knee_pitch_link" />
    <origin xyz="0.006 0.021 -0.18" rpy="0 0 0" />
    <axis xyz="0 1 0"/>
    <limit effort="1000.0" lower="-2" upper="2" velocity="0.5"/>
  </joint>
  <link name="left_knee_pitch_link">
    <visual><origin xyz="0 0 -0.1" rpy="0 0 0" /><geometry><cylinder radius="0.01" length="0.2" /></geometry></visual>
    <collision><origin xyz="0 0 -0.1" rpy="0 0 0" /><geometry><sphere radius="0.01" /></geometry></collision>
    <inertial><origin xyz="0 0 -0.1" rpy="0 0 0" /><mass value="1" /><inertia ixx="0.4" ixy="0" ixz="0" iyy="0.4" iyz="0" izz="0.4" /></inertial>
  </link>

  <joint name="left_ankle_pitch_joint" type="revolute">
    <parent link="left_knee_pitch_link" />
    <child link="left_ankle_pitch_link" />
    <origin xyz="0.04 0 -0.22" rpy="0 0 0" />
    <axis xyz="0 1 0"/>
    <limit effort="1000.0" lower="-2" upper="2" velocity="0.5"/>
  </joint>
  <link name="left_ankle_pitch_link">
    <visual><origin xyz="0 0 0" rpy="0 0 0" /><geometry><sphere radius="0.01" /></geometry></visual>
    <collision><origin xyz="0 0 0" rpy="0 0 0" /><geometry><sphere radius="0.01" /></geometry></collision>
    <inertial><origin xyz="0 0 0" rpy="0 0 0" /><mass value="1" /><inertia ixx="0.4" ixy="0" ixz="0" iyy="0.4" iyz="0" izz="0.4" /></inertial>
  </link>

  <joint name="left_ankle_roll_joint" type="revolute">
    <parent link="left_ankle_pitch_link" />
    <child link="left_ankle_roll_link" />
    <origin xyz="0 0 0" rpy="0 0 0" />
    <axis xyz="1 0 0"/>
    <limit effort="1000.0" lower="-2" upper="2" velocity="0.5"/>
  </joint>
  <link name="left_ankle_roll_link">
    <visual><origin xyz="-0.01 0 0" rpy="0 0 0" /><geometry><box size="0.08 0.04 0.01" /></geometry></visual>
    <collision><origin xyz="-0.01 0 0" rpy="0 0 0" /><geometry><sphere radius="0.01" /></geometry></collision>
    <inertial><origin xyz="-0.01 0 0" rpy="0 0 0" /><mass value="1" /><inertia ixx="0.4" ixy="0" ixz="0" iyy="0.4" iyz="0" izz="0.4" /></inertial>
  </link>

  <!-- ========= WAIST / TORSO ========= -->
  <joint name="waist_yaw_joint" type="revolute">
    <parent link="base_link" />
    <child link="waist_yaw_link" />
    <origin xyz="0.005 0 0.1471" rpy="0 0 0" />
    <axis xyz="0 0 1"/>
    <limit effort="1000.0" lower="-2" upper="2" velocity="0.5"/>
  </joint>
  <link name="waist_yaw_link">
    <visual><origin xyz="0 0 0" rpy="0 0 0" /><geometry><sphere radius="0.01" /></geometry></visual>
    <collision><origin xyz="0 0 0" rpy="0 0 0" /><geometry><sphere radius="0.01" /></geometry></collision>
    <inertial><origin xyz="0 0 0" rpy="0 0 0" /><mass value="1" /><inertia ixx="0.4" ixy="0" ixz="0" iyy="0.4" iyz="0" izz="0.4" /></inertial>
  </link>

  <joint name="waist_roll_joint" type="revolute">
    <parent link="waist_yaw_link" />
    <child link="waist_roll_link" />
    <origin xyz="0 0 0" rpy="0 0 0" />
    <axis xyz="1 0 0"/>
    <limit effort="1000.0" lower="-2" upper="2" velocity="0.5"/>
  </joint>
  <link name="waist_roll_link">
    <visual><origin xyz="0 0 0" rpy="0 0 0" /><geometry><sphere radius="0.01" /></geometry></visual>
    <collision><origin xyz="0 0 0" rpy="0 0 0" /><geometry><sphere radius="0.01" /></geometry></collision>
    <inertial><origin xyz="0 0 0" rpy="0 0 0" /><mass value="1" /><inertia ixx="0.4" ixy="0" ixz="0" iyy="0.4" iyz="0" izz="0.4" /></inertial>
  </link>

  <joint name="waist_pitch_joint" type="revolute">
    <parent link="waist_roll_link" />
    <child link="waist_pitch_link" />
    <origin xyz="0 0 0" rpy="0 0 0" />
    <axis xyz="0 1 0"/>
    <limit effort="1000.0" lower="-2" upper="2" velocity="0.5"/>
  </joint>
  <link name="waist_pitch_link">
    <visual><origin xyz="0 0 -0.025" rpy="0 0 0" /><geometry><box size="0.1 0.08 0.14" /></geometry></visual>
    <collision><origin xyz="0 0 -0.025" rpy="0 0 0" /><geometry><sphere radius="0.01" /></geometry></collision>
    <inertial><origin xyz="0 0 -0.025" rpy="0 0 0" /><mass value="1" /><inertia ixx="0.4" ixy="0" ixz="0" iyy="0.4" iyz="0" izz="0.4" /></inertial>
  </link>

  <!-- ========= LEFT ARM ========= -->
  <joint name="left_shoulder_pitch_joint" type="revolute">
    <parent link="waist_pitch_link" />
    <child link="left_shoulder_pitch_link" />
    <origin xyz="-0.01 0.085 0.063" rpy="0 0 0" />
    <axis xyz="1 0 0"/>
    <limit effort="1000.0" lower="-2" upper="2" velocity="0.5"/>
  </joint>
  <link name="left_shoulder_pitch_link">
    <visual><origin xyz="0 0 0" rpy="0 0 0" /><geometry><sphere radius="0.01" /></geometry></visual>
    <collision><origin xyz="0 0 0" rpy="0 0 0" /><geometry><sphere radius="0.01" /></geometry></collision>
    <inertial><origin xyz="0 0 0" rpy="0 0 0" /><mass value="1" /><inertia ixx="0.4" ixy="0" ixz="0" iyy="0.4" iyz="0" izz="0.4" /></inertial>
  </link>

  <joint name="left_shoulder_roll_joint" type="revolute">
    <parent link="left_shoulder_pitch_link" />
    <child link="left_shoulder_roll_link" />
    <origin xyz="0 0 0" rpy="0 0 0" />
    <axis xyz="0 1 0"/>
    <limit effort="1000.0" lower="-2" upper="2" velocity="0.5"/>
  </joint>
  <link name="left_shoulder_roll_link">
    <visual><origin xyz="0 0 0" rpy="0 0 0" /><geometry><sphere radius="0.01" /></geometry></visual>
    <collision><origin xyz="0 0 0" rpy="0 0 0" /><geometry><sphere radius="0.01" /></geometry></collision>
    <inertial><origin xyz="0 0 0" rpy="0 0 0" /><mass value="1" /><inertia ixx="0.4" ixy="0" ixz="0" iyy="0.4" iyz="0" izz="0.4" /></inertial>
  </link>

  <joint name="left_shoulder_yaw_joint" type="revolute">
    <parent link="left_shoulder_roll_link" />
    <child link="left_shoulder_yaw_link" />
    <origin xyz="0 0 0" rpy="0 0 0" />
    <axis xyz="0 0 1"/>
    <limit effort="1000.0" lower="-2" upper="2" velocity="0.5"/>
  </joint>
  <link name="left_shoulder_yaw_link">
    <visual><origin xyz="-0.027955245865531952 0.06 -0.03" rpy="0 0 0" /><geometry><box size="0.02 0.12 0.02" /></geometry></visual>
    <collision><origin xyz="-0.027955245865531952 0.06 -0.03" rpy="0 0 0" /><geometry><sphere radius="0.01" /></geometry></collision>
    <inertial><origin xyz="-0.027955245865531952 0.06 -0.03" rpy="0 0 0" /><mass value="1" /><inertia ixx="0.4" ixy="0" ixz="0" iyy="0.4" iyz="0" izz="0.4" /></inertial>
  </link>

  <joint name="left_elbow_pitch_joint" type="revolute">
    <parent link="left_shoulder_yaw_link" />
    <child link="left_elbow_pitch_link" />
    <origin xyz="-0.024 0.12 -0.03" rpy="0 0 0" />
    <axis xyz="0 0 1"/>
    <limit effort="1000.0" lower="-2" upper="2" velocity="0.5"/>
  </joint>
  <link name="left_elbow_pitch_link">
    <visual><origin xyz="0 0.06 0" rpy="0 0 0" /><geometry><box size="0.02 0.12 0.02" /></geometry></visual>
    <collision><origin xyz="0 0.06 0" rpy="0 0 0" /><geometry><sphere radius="0.01" /></geometry></collision>
    <inertial><origin xyz="0 0.06 0" rpy="0 0 0" /><mass value="1" /><inertia ixx="0.4" ixy="0" ixz="0" iyy="0.4" iyz="0" izz="0.4" /></inertial>
  </link>

  <!-- ========= RIGHT LEG ========= -->
  <joint name="right_hip_pitch_joint" type="revolute">
    <parent link="base_link" />
    <child link="right_hip_pitch_link" />
    <origin xyz="0 -0.026 -0.043" rpy="0 0 0" />
    <axis xyz="0 1 0"/>
    <limit effort="1000.0" lower="-2" upper="2" velocity="0.5"/>
  </joint>
  <link name="right_hip_pitch_link">
    <visual><origin xyz="0 0 0" rpy="0 0 0" /><geometry><sphere radius="0.01" /></geometry></visual>
    <collision><origin xyz="0 0 0" rpy="0 0 0" /><geometry><sphere radius="0.01" /></geometry></collision>
    <inertial><origin xyz="0 0 0" rpy="0 0 0" /><mass value="1" /><inertia ixx="0.4" ixy="0" ixz="0" iyy="0.4" iyz="0" izz="0.4" /></inertial>
  </link>

  <joint name="right_hip_roll_joint" type="revolute">
    <parent link="right_hip_pitch_link" />
    <child link="right_hip_roll_link" />
    <origin xyz="0 0 0" rpy="0 0 0" />
    <axis xyz="1 0 0"/>
    <limit effort="1000.0" lower="-1" upper="1" velocity="0.5"/>
  </joint>
  <link name="right_hip_roll_link">
    <visual><origin xyz="0 0 0" rpy="0 0 0" /><geometry><sphere radius="0.01" /></geometry></visual>
    <collision><origin xyz="0 0 0" rpy="0 0 0" /><geometry><sphere radius="0.01" /></geometry></collision>
    <inertial><origin xyz="0 0 0" rpy="0 0 0" /><mass value="1" /><inertia ixx="0.4" ixy="0" ixz="0" iyy="0.4" iyz="0" izz="0.4" /></inertial>
  </link>

  <joint name="right_hip_yaw_joint" type="revolute">
    <parent link="right_hip_roll_link" />
    <child link="right_hip_yaw_link" />
    <origin xyz="0 0 0" rpy="0 0 0" />
    <axis xyz="0 0 1"/>
    <limit effort="1000.0" lower="-2" upper="2" velocity="0.5"/>
  </joint>
  <link name="right_hip_yaw_link">
    <visual><origin xyz="0.005 -0.021 -0.08" rpy="0 0 0" /><geometry><cylinder radius="0.01" length="0.16" /></geometry></visual>
    <collision><origin xyz="0.005 -0.021 -0.08" rpy="0 0 0" /><geometry><sphere radius="0.01" /></geometry></collision>
    <inertial><origin xyz="0.005 -0.021 -0.08" rpy="0 0 0" /><mass value="1" /><inertia ixx="0.4" ixy="0" ixz="0" iyy="0.4" iyz="0" izz="0.4" /></inertial>
  </link>

  <joint name="right_knee_pitch_joint" type="revolute">
    <parent link="right_hip_yaw_link" />
    <child link="right_knee_pitch_link" />
    <origin xyz="0.006 -0.021 -0.18" rpy="0 0 0" />
    <axis xyz="0 1 0"/>
    <limit effort="1000.0" lower="-2" upper="2" velocity="0.5"/>
  </joint>
  <link name="right_knee_pitch_link">
    <visual><origin xyz="0 0 -0.1" rpy="0 0 0" /><geometry><cylinder radius="0.01" length="0.2" /></geometry></visual>
    <collision><origin xyz="0 0 -0.1" rpy="0 0 0" /><geometry><sphere radius="0.01" /></geometry></collision>
    <inertial><origin xyz="0 0 -0.1" rpy="0 0 0" /><mass value="1" /><inertia ixx="0.4" ixy="0" ixz="0" iyy="0.4" iyz="0" izz="0.4" /></inertial>
  </link>

  <joint name="right_ankle_pitch_joint" type="revolute">
    <parent link="right_knee_pitch_link" />
    <child link="right_ankle_pitch_link" />
    <origin xyz="0.04 0 -0.22" rpy="0 0 0" />
    <axis xyz="0 1 0"/>
    <limit effort="1000.0" lower="-2" upper="2" velocity="0.5"/>
  </joint>
  <link name="right_ankle_pitch_link">
    <visual><origin xyz="0 0 0" rpy="0 0 0" /><geometry><sphere radius="0.01" /></geometry></visual>
    <collision><origin xyz="0 0 0" rpy="0 0 0" /><geometry><sphere radius="0.01" /></geometry></collision>
    <inertial><origin xyz="0 0 0" rpy="0 0 0" /><mass value="1" /><inertia ixx="0.4" ixy="0" ixz="0" iyy="0.4" iyz="0" izz="0.4" /></inertial>
  </link>

  <joint name="right_ankle_roll_joint" type="revolute">
    <parent link="right_ankle_pitch_link" />
    <child link="right_ankle_roll_link" />
    <origin xyz="0 0 0" rpy="0 0 0" />
    <axis xyz="1 0 0"/>
    <limit effort="1000.0" lower="-2" upper="2" velocity="0.5"/>
  </joint>
  <link name="right_ankle_roll_link">
    <visual><origin xyz="-0.01 0 0" rpy="0 0 0" /><geometry><box size="0.08 0.04 0.01" /></geometry></visual>
    <collision><origin xyz="-0.01 0 0" rpy="0 0 0" /><geometry><sphere radius="0.01" /></geometry></collision>
    <inertial><origin xyz="-0.01 0 0" rpy="0 0 0" /><mass value="1" /><inertia ixx="0.4" ixy="0" ixz="0" iyy="0.4" iyz="0" izz="0.4" /></inertial>
  </link>

  <!-- ========= RIGHT ARM ========= -->
  <joint name="right_shoulder_pitch_joint" type="revolute">
    <parent link="waist_pitch_link" />
    <child link="right_shoulder_pitch_link" />
    <origin xyz="-0.01 -0.085 0.063" rpy="0 0 0" />
    <axis xyz="1 0 0"/>
    <limit effort="1000.0" lower="-2" upper="2" velocity="0.5"/>
  </joint>
  <link name="right_shoulder_pitch_link">
    <visual><origin xyz="0 0 0" rpy="0 0 0" /><geometry><sphere radius="0.01" /></geometry></visual>
    <collision><origin xyz="0 0 0" rpy="0 0 0" /><geometry><sphere radius="0.01" /></geometry></collision>
    <inertial><origin xyz="0 0 0" rpy="0 0 0" /><mass value="1" /><inertia ixx="0.4" ixy="0" ixz="0" iyy="0.4" iyz="0" izz="0.4" /></inertial>
  </link>

  <joint name="right_shoulder_roll_joint" type="revolute">
    <parent link="right_shoulder_pitch_link" />
    <child link="right_shoulder_roll_link" />
    <origin xyz="0 0 0" rpy="0 0 0" />
    <axis xyz="0 1 0"/>
    <limit effort="1000.0" lower="-2" upper="2" velocity="0.5"/>
  </joint>
  <link name="right_shoulder_roll_link">
    <visual><origin xyz="0 0 0" rpy="0 0 0" /><geometry><sphere radius="0.01" /></geometry></visual>
    <collision><origin xyz="0 0 0" rpy="0 0 0" /><geometry><sphere radius="0.01" /></geometry></collision>
    <inertial><origin xyz="0 0 0" rpy="0 0 0" /><mass value="1" /><inertia ixx="0.4" ixy="0" ixz="0" iyy="0.4" iyz="0" izz="0.4" /></inertial>
  </link>

  <joint name="right_shoulder_yaw_joint" type="revolute">
    <parent link="right_shoulder_roll_link" />
    <child link="right_shoulder_yaw_link" />
    <origin xyz="0 0 0" rpy="0 0 0" />
    <axis xyz="0 0 1"/>
    <limit effort="1000.0" lower="-2" upper="2" velocity="0.5"/>
  </joint>
  <link name="right_shoulder_yaw_link">
    <visual><origin xyz="-0.027955245865531952 -0.06 -0.03" rpy="0 0 0" /><geometry><box size="0.02 0.12 0.02" /></geometry></visual>
    <collision><origin xyz="-0.027955245865531952 -0.06 -0.03" rpy="0 0 0" /><geometry><sphere radius="0.01" /></geometry></collision>
    <inertial><origin xyz="-0.027955245865531952 -0.06 -0.03" rpy="0 0 0" /><mass value="1" /><inertia ixx="0.4" ixy="0" ixz="0" iyy="0.4" iyz="0" izz="0.4" /></inertial>
  </link>

  <joint name="right_elbow_pitch_joint" type="revolute">
    <parent link="right_shoulder_yaw_link" />
    <child link="right_elbow_pitch_link" />
    <origin xyz="-0.024 -0.12 -0.03" rpy="0 0 0" />
    <axis xyz="0 0 1"/>
    <limit effort="1000.0" lower="-2" upper="2" velocity="0.5"/>
  </joint>
  <link name="right_elbow_pitch_link">
    <visual><origin xyz="0 -0.06 0" rpy="0 0 0" /><geometry><box size="0.02 0.12 0.02" /></geometry></visual>
    <collision><origin xyz="0 -0.06 0" rpy="0 0 0" /><geometry><sphere radius="0.01" /></geometry></collision>
    <inertial><origin xyz="0 -0.06 0" rpy="0 0 0" /><mass value="1" /><inertia ixx="0.4" ixy="0" ixz="0" iyy="0.4" iyz="0" izz="0.4" /></inertial>
  </link>

</robot>
