<mujoco model="robot">
  <compiler angle="radian" meshdir="meshes/"/>

  <worldbody>
    <body name="base_link">
      <inertial pos="0 0 0" mass="1" diaginertia="0.4 0.4 0.4"/>
      <joint name="floating_base_joint" type="free"/>
      <geom size="0.01" contype="0" conaffinity="0" group="1" density="0"/>
      <geom size="0.01"/>
      <body name="left_hip_pitch_link" pos="0 0.026 -0.043">
        <inertial pos="0 0 0" mass="1" diaginertia="0.4 0.4 0.4"/>
        <joint name="left_hip_pitch_joint" pos="0 0 0" axis="0 1 0" range="-2 2" actuatorfrcrange="-1000 1000"/>
        <geom size="0.01" contype="0" conaffinity="0" group="1" density="0"/>
        <geom size="0.01"/>
        <body name="left_hip_roll_link">
          <inertial pos="0 0 0" mass="1" diaginertia="0.4 0.4 0.4"/>
          <joint name="left_hip_roll_joint" pos="0 0 0" axis="1 0 0" range="-1 1" actuatorfrcrange="-1000 1000"/>
          <geom size="0.01" contype="0" conaffinity="0" group="1" density="0"/>
          <geom size="0.01"/>
          <body name="left_hip_yaw_link">
            <inertial pos="0.005 0.021 -0.08" mass="1" diaginertia="0.4 0.4 0.4"/>
            <joint name="left_hip_yaw_joint" pos="0 0 0" axis="0 0 1" range="-2 2" actuatorfrcrange="-1000 1000"/>
            <geom size="0.01 0.08" pos="0.005 0.021 -0.08" type="cylinder" contype="0" conaffinity="0" group="1" density="0"/>
            <geom size="0.01" pos="0.005 0.021 -0.08"/>
            <body name="left_knee_pitch_link" pos="0.006 0.021 -0.18">
              <inertial pos="0 0 -0.1" mass="1" diaginertia="0.4 0.4 0.4"/>
              <joint name="left_knee_pitch_joint" pos="0 0 0" axis="0 1 0" range="-2 2" actuatorfrcrange="-1000 1000"/>
              <geom size="0.01 0.1" pos="0 0 -0.1" type="cylinder" contype="0" conaffinity="0" group="1" density="0"/>
              <geom size="0.01" pos="0 0 -0.1"/>
              <body name="left_ankle_pitch_link" pos="0.04 0 -0.22">
                <inertial pos="0 0 0" mass="1" diaginertia="0.4 0.4 0.4"/>
                <joint name="left_ankle_pitch_joint" pos="0 0 0" axis="0 1 0" range="-2 2" actuatorfrcrange="-1000 1000"/>
                <geom size="0.01" contype="0" conaffinity="0" group="1" density="0"/>
                <geom size="0.01"/>
                <body name="left_ankle_roll_link">
                  <inertial pos="-0.01 0 0" mass="1" diaginertia="0.4 0.4 0.4"/>
                  <joint name="left_ankle_roll_joint" pos="0 0 0" axis="1 0 0" range="-2 2" actuatorfrcrange="-1000 1000"/>
                  <geom size="0.04 0.02 0.005" pos="-0.01 0 0" type="box" contype="0" conaffinity="0" group="1" density="0"/>
                  <geom size="0.01" pos="-0.01 0 0"/>
                </body>
              </body>
            </body>
          </body>
        </body>
      </body>
      <body name="waist_yaw_link" pos="0.005 0 0.1471">
        <inertial pos="0 0 0" mass="1" diaginertia="0.4 0.4 0.4"/>
        <joint name="waist_yaw_joint" pos="0 0 0" axis="0 0 1" range="-2 2" actuatorfrcrange="-1000 1000"/>
        <geom size="0.01" contype="0" conaffinity="0" group="1" density="0"/>
        <geom size="0.01"/>
        <body name="waist_roll_link">
          <inertial pos="0 0 0" mass="1" diaginertia="0.4 0.4 0.4"/>
          <joint name="waist_roll_joint" pos="0 0 0" axis="1 0 0" range="-2 2" actuatorfrcrange="-1000 1000"/>
          <geom size="0.01" contype="0" conaffinity="0" group="1" density="0"/>
          <geom size="0.01"/>
          <body name="waist_pitch_link">
            <inertial pos="0 0 -0.025" mass="1" diaginertia="0.4 0.4 0.4"/>
            <joint name="waist_pitch_joint" pos="0 0 0" axis="0 1 0" range="-2 2" actuatorfrcrange="-1000 1000"/>
            <geom size="0.05 0.04 0.07" pos="0 0 -0.025" type="box" contype="0" conaffinity="0" group="1" density="0"/>
            <geom size="0.01" pos="0 0 -0.025"/>
            <body name="left_shoulder_pitch_link" pos="-0.01 0.085 0.063">
              <inertial pos="0 0 0" mass="1" diaginertia="0.4 0.4 0.4"/>
              <joint name="left_shoulder_pitch_joint" pos="0 0 0" axis="1 0 0" range="-2 2" actuatorfrcrange="-1000 1000"/>
              <geom size="0.01" contype="0" conaffinity="0" group="1" density="0"/>
              <geom size="0.01"/>
              <body name="left_shoulder_roll_link">
                <inertial pos="0 0 0" mass="1" diaginertia="0.4 0.4 0.4"/>
                <joint name="left_shoulder_roll_joint" pos="0 0 0" axis="0 1 0" range="-2 2" actuatorfrcrange="-1000 1000"/>
                <geom size="0.01" contype="0" conaffinity="0" group="1" density="0"/>
                <geom size="0.01"/>
                <body name="left_shoulder_yaw_link">
                  <inertial pos="-0.0279552 0.06 -0.03" mass="1" diaginertia="0.4 0.4 0.4"/>
                  <joint name="left_shoulder_yaw_joint" pos="0 0 0" axis="0 0 1" range="-2 2" actuatorfrcrange="-1000 1000"/>
                  <geom size="0.01 0.06 0.01" pos="-0.0279552 0.06 -0.03" type="box" contype="0" conaffinity="0" group="1" density="0"/>
                  <geom size="0.01" pos="-0.0279552 0.06 -0.03"/>
                  <body name="left_elbow_pitch_link" pos="-0.024 0.12 -0.03">
                    <inertial pos="0 0.06 0" mass="1" diaginertia="0.4 0.4 0.4"/>
                    <joint name="left_elbow_pitch_joint" pos="0 0 0" axis="0 0 1" range="-2 2" actuatorfrcrange="-1000 1000"/>
                    <geom size="0.01 0.06 0.01" pos="0 0.06 0" type="box" contype="0" conaffinity="0" group="1" density="0"/>
                    <geom size="0.01" pos="0 0.06 0"/>
                  </body>
                </body>
              </body>
            </body>
            <body name="right_shoulder_pitch_link" pos="-0.01 -0.085 0.063">
              <inertial pos="0 0 0" mass="1" diaginertia="0.4 0.4 0.4"/>
              <joint name="right_shoulder_pitch_joint" pos="0 0 0" axis="1 0 0" range="-2 2" actuatorfrcrange="-1000 1000"/>
              <geom size="0.01" contype="0" conaffinity="0" group="1" density="0"/>
              <geom size="0.01"/>
              <body name="right_shoulder_roll_link">
                <inertial pos="0 0 0" mass="1" diaginertia="0.4 0.4 0.4"/>
                <joint name="right_shoulder_roll_joint" pos="0 0 0" axis="0 1 0" range="-2 2" actuatorfrcrange="-1000 1000"/>
                <geom size="0.01" contype="0" conaffinity="0" group="1" density="0"/>
                <geom size="0.01"/>
                <body name="right_shoulder_yaw_link">
                  <inertial pos="-0.0279552 -0.06 -0.03" mass="1" diaginertia="0.4 0.4 0.4"/>
                  <joint name="right_shoulder_yaw_joint" pos="0 0 0" axis="0 0 1" range="-2 2" actuatorfrcrange="-1000 1000"/>
                  <geom size="0.01 0.06 0.01" pos="-0.0279552 -0.06 -0.03" type="box" contype="0" conaffinity="0" group="1" density="0"/>
                  <geom size="0.01" pos="-0.0279552 -0.06 -0.03"/>
                  <body name="right_elbow_pitch_link" pos="-0.024 -0.12 -0.03">
                    <inertial pos="0 -0.06 0" mass="1" diaginertia="0.4 0.4 0.4"/>
                    <joint name="right_elbow_pitch_joint" pos="0 0 0" axis="0 0 1" range="-2 2" actuatorfrcrange="-1000 1000"/>
                    <geom size="0.01 0.06 0.01" pos="0 -0.06 0" type="box" contype="0" conaffinity="0" group="1" density="0"/>
                    <geom size="0.01" pos="0 -0.06 0"/>
                  </body>
                </body>
              </body>
            </body>
          </body>
        </body>
      </body>
      <body name="right_hip_pitch_link" pos="0 -0.026 -0.043">
        <inertial pos="0 0 0" mass="1" diaginertia="0.4 0.4 0.4"/>
        <joint name="right_hip_pitch_joint" pos="0 0 0" axis="0 1 0" range="-2 2" actuatorfrcrange="-1000 1000"/>
        <geom size="0.01" contype="0" conaffinity="0" group="1" density="0"/>
        <geom size="0.01"/>
        <body name="right_hip_roll_link">
          <inertial pos="0 0 0" mass="1" diaginertia="0.4 0.4 0.4"/>
          <joint name="right_hip_roll_joint" pos="0 0 0" axis="1 0 0" range="-1 1" actuatorfrcrange="-1000 1000"/>
          <geom size="0.01" contype="0" conaffinity="0" group="1" density="0"/>
          <geom size="0.01"/>
          <body name="right_hip_yaw_link">
            <inertial pos="0.005 -0.021 -0.08" mass="1" diaginertia="0.4 0.4 0.4"/>
            <joint name="right_hip_yaw_joint" pos="0 0 0" axis="0 0 1" range="-2 2" actuatorfrcrange="-1000 1000"/>
            <geom size="0.01 0.08" pos="0.005 -0.021 -0.08" type="cylinder" contype="0" conaffinity="0" group="1" density="0"/>
            <geom size="0.01" pos="0.005 -0.021 -0.08"/>
            <body name="right_knee_pitch_link" pos="0.006 -0.021 -0.18">
              <inertial pos="0 0 -0.1" mass="1" diaginertia="0.4 0.4 0.4"/>
              <joint name="right_knee_pitch_joint" pos="0 0 0" axis="0 1 0" range="-2 2" actuatorfrcrange="-1000 1000"/>
              <geom size="0.01 0.1" pos="0 0 -0.1" type="cylinder" contype="0" conaffinity="0" group="1" density="0"/>
              <geom size="0.01" pos="0 0 -0.1"/>
              <body name="right_ankle_pitch_link" pos="0.04 0 -0.22">
                <inertial pos="0 0 0" mass="1" diaginertia="0.4 0.4 0.4"/>
                <joint name="right_ankle_pitch_joint" pos="0 0 0" axis="0 1 0" range="-2 2" actuatorfrcrange="-1000 1000"/>
                <geom size="0.01" contype="0" conaffinity="0" group="1" density="0"/>
                <geom size="0.01"/>
                <body name="right_ankle_roll_link">
                  <inertial pos="-0.01 0 0" mass="1" diaginertia="0.4 0.4 0.4"/>
                  <joint name="right_ankle_roll_joint" pos="0 0 0" axis="1 0 0" range="-2 2" actuatorfrcrange="-1000 1000"/>
                  <geom size="0.04 0.02 0.005" pos="-0.01 0 0" type="box" contype="0" conaffinity="0" group="1" density="0"/>
                  <geom size="0.01" pos="-0.01 0 0"/>
                </body>
              </body>
            </body>
          </body>
        </body>
      </body>
    </body>
  </worldbody>
  <!-- setup scene -->
  <statistic center="1.0 0.7 1.0" extent="0.8"/>
  <visual>
    <headlight diffuse="0.6 0.6 0.6" ambient="0.1 0.1 0.1" specular="0.9 0.9 0.9"/>
    <rgba haze="0.15 0.25 0.35 1"/>
    <global azimuth="-140" elevation="-20" offwidth="2080" offheight="1170"/>
  </visual>
  <asset>
     <texture type="skybox" builtin="gradient" rgb1="1 1 1" rgb2="1 1 1" width="800" height="800"/>
    <texture type="2d" name="groundplane" builtin="checker" mark="edge" rgb1="1 1 1" rgb2="1 1 1" markrgb="0 0 0"
      width="300" height="300"/>
    <material name="groundplane" texture="groundplane" texuniform="true" texrepeat="5 5" reflectance="0"/>
    <texture type="skybox" builtin="gradient" rgb1=".4 .5 .6" rgb2="0 0 0" width="100" height="100"/>
    <texture builtin="flat" height="1278" mark="cross" markrgb="1 1 1" name="texgeom" random="0.01" rgb1="0.8 0.6 0.4" rgb2="0.8 0.6 0.4" type="cube" width="127"/>
    <texture name="texplane" builtin="checker" height="512" width="512" rgb1=".2 .3 .4" rgb2=".1 .15 .2" type="2d" />
    <material name="MatPlane" reflectance="0.5" shininess="0.01" specular="0.1" texrepeat="1 1" texture="texplane" texuniform="true" />
    <material name="geom" texture="texgeom" texuniform="true"/>
  </asset>
   <worldbody>
    <geom name="floor" size="0 0 0.01" type="plane" material="groundplane" contype="1" conaffinity="0" priority="1"
      friction="0.6" condim="3"/>

        <light diffuse=".5 .5 .5" pos="-3 -3 5" dir="3 3 -5" castshadow="true"/>

  </worldbody>
</mujoco>
